Workbook
Name Slicer_Company: #N/A
Name Slicer_Industry: #N/A
Name Slicer_Industry1: #N/A
Name Slicer_Total_Jobs: #N/A

Sheet postings
A1: job_title | B1: company | C1: job_location | D1: job_link | E1: first_seen | F1: search_city | G1: search_country | H1: job level | I1: job_type | J1: job_summary | K1: job_skills
A2: Data Engineer 2 | B2: Cook Medical | C2: Bloomington, IN | D2: https://www.linkedin.com/jobs/view/data-engineer-2-at-cook-medical-3526207414 | E2: 45277 | F2: Bloomington | G2: United States | H2: Mid senior | I2: Onsite | J2: Overview The Data Engineer develops, implements and documents data systems that provide the technical solutions to meet specifications and business requirements defined by company objectives to promote effective, efficient, and compliant operations. Experience with Azure preferrable. Experience with relational SQL and NoSQL databases; experience with SQL Server, Azure, Oracle, and/or MongoDB preferred. Hybird or Remote position with expectation of Eastern Time Zone Hours. Responsibilities Work as part of a project team to define and document data and data pipelines for a variety of solutions. Technical responsibility for data and data pipelines to ensure compliance with data standards, architectural standards, and achievement of documented requirements. Develop and maintain current state documentation and deliverables for data solutions. Maintain existing and new data solutions to ensure that they continue to meet user needs. Provide assistance to operational teams to ensure continuity of service. Work with the Data Engineering community of practice to identify and implement continuous improvement opportunities. Must have excellent analytical and problem solving skills Performs other duties as assigned Possesses solid working knowledge of subject matter. May provide leadership, coaching, and/or mentoring to a subordinate group. Ability to manage tasks independently and take ownership of responsibilities Performs work under minimal supervision. Demonstrated organizational, analytical and interpersonal skills Must work and interact effectively and professionally with and for others throughout various levels of the global organization Must have effective communication skills and ability to work in a collaborative and independent work situations and environments with minimal supervision Ability to remain calm and receptive in fast paced situations Ability to manage tasks independently; take ownership of responsibilities Qualifications Bachelors Degree in Computer Science or other related degree; or experience of such kind and amount as to provide a comparable background. Experience with relational SQL and NoSQL databases; experience with SQL Server, Oracle, and/or MongoDB preferred. Preferrable 4-6 years of experience as Data Engineer Experience building data transformations, data structures, and data pipelines. Experience with data integration tools. Experience with object-oriented/object function scripting languages. Demonstrated organizational, analytical and interpersonal skills Ability to manage tasks independently; take ownership of responsibilities Physical Requirements Works under general office environment conditions Sitting for extended periods, utilizes close visual acuity for working with computers, equipment, etc. Must be able to perform the essential functions of the job, subject to reasonable accommodation requirements under the ADA Requires occasional early morning or late evening teleconferences International and domestic travel as required For this position, qualified candidates must be legally authorized to be employed in the United States. Cook does not intend to provide sponsorship for employment visa status (e.g., H-1B or TN status) for this employment position. Show more Show less | K2: Azure, SQL, NoSQL, SQL Server, Oracle, MongoDB, Data pipelines, Data integration tools, Objectoriented/object function scripting languages
A3: Staff Data Engineer | B3: Recruiting from Scratch | C3: Bloomington, IN | D3: https://www.linkedin.com/jobs/view/staff-data-engineer-at-recruiting-from-scratch-3744389892 | E3: 45277 | F3: Bloomington | G3: United States | H3: Mid senior | I3: Onsite | J3: This is for a client of Recruiting from Scratch. Who is Recruiting from Scratch: Recruiting from Scratch is a premier talent firm that focuses on placing the best product managers, software, and hardware talent at innovative companies. Our team is 100% remote and we work with teams across the United States to help them hire. We work with companies funded by the best investors including Sequoia Capital, Lightspeed Ventures, Tiger Global Management, A16Z, Accel, DFJ, and more. Our Client: Our client is a dating app. In this role, you will have the opportunity to work with our product teams, building models and APIs to drive new features, deliver analysis to further improve engagement in existing features, and empower our business with real-time insights to drive growth in market share, engagement, and revenue. We see 1 trillion events per year and process 10TB of data daily. What’s the job? Design, develop and deliver data products to production, complying with internal data governance, security and scalability of our system. Solve technical problems of the highest scope and complexity Exert significant influence on the company’s analytical long-range goals and data architecture Define and extend our internal standards for style, maintenance, and best practices for a high-scale data platform Provide mentorship for all on your team to help them grow in their technical responsibilities Propose ideas to improve the scale, performance, and capabilities of the Data Platform Moving implementation to ownership of real-time and batch processing and data governance and policies. Maintain and enforce the business contracts on how data should be represented and stored. Stay on top of new technologies through R&D and prototyping to continuously improve our big data architectures and systems to streamline how we deliver value with high quality to our end users Implementing ETL processes, moving data between systems including S3, Snowflake, Kafka, and Spark. Work closely with our Data Scientists, SREs, and Product Managers to ensure software is high quality and meets user requirements. What We'll Love About You 7+ years of experience working with data at scale, including data engineering, business intelligence, data science, or related field 7+ years experience using Python Experience using big data technologies (Snowflake, Airflow, Kubernetes, Docker, Helm, Spark, pySpark) Significant experience with relational databases and query authoring (SQL) in Snowflake or other distributed Databases Experience with agile engineering practices such as TDD, Pair Programming, Continuous Integration, automated testing, and deployment Experience with building stream-processing systems, using solutions such as Kafka, Storm or Spark-Streaming Experience with dimensional data modeling and schema design in Data Warehouses Familiar with ETL (managing high-quality reliable ETL pipelines) Be familiar with legal compliance (with data management tools) data classification, and retention Location : This role will be located in office twice a week minimum in Palo Alto, San Francisco or Chicago. Salary Range: $180,000 - 250,000 USD base. Equity. Medical, Dental, Vision. https://www.recruitingfromscratch.com/ Show more Show less | K3: Python, Snowflake, Airflow, Kubernetes, Docker, Helm, Spark, pySpark, SQL, TDD, Pair Programming, Continuous Integration, automated testing, Kafka, Storm, SparkStreaming, dimensional data modeling, ETL, data management, data classification
A4: Senior Data Engineer, Public Company | B4: Recruiting from Scratch | C4: Bloomington, IN | D4: https://www.linkedin.com/jobs/view/senior-data-engineer-public-company-at-recruiting-from-scratch-3748828472 | E4: 45277 | F4: Bloomington | G4: United States | H4: Mid senior | I4: Onsite | J4: This is for a client of Recruiting from Scratch. Who is Recruiting from Scratch: Recruiting from Scratch is a premier talent firm that focuses on placing the best product managers, software, and hardware talent at innovative companies. Our team is 100% remote and we work with teams across the United States to help them hire. We work with companies funded by the best investors including Sequoia Capital, Lightspeed Ventures, Tiger Global Management, A16Z, Accel, DFJ, and more. Our Client: Our next evolution is underway as a newly public company looking to expand and continue to build meaningful experiences for our users. From social issues to original content, we’re blazing innovative paths with impact for our community, all while leveraging the latest tech stacks and striving for engineering excellence. At the heart of our work in this new chapter is a shared set of core values: openness and exploration, a bias for action, and strong support of the LGBTQ community. With a track record of strong financial performance and plans for continued headcount growth, we’re looking to build a team of talented, passionate, and open-minded people who believe in our mission, align with our values, and are excited to work at the intersection of innovative technology and social impact. Come be a part of this exciting journey with us. What’s so interesting about this role? Our client is looking to bring on a Senior Data Engineer with chops in cutting edge real-time streaming technologies and ambitions to achieve high quality and reliability with TDD, automation, and continuous delivery. . In this role, you will have the opportunity to work with our product teams, building models and APIs to drive new features, delivers analysis to further improve engagement in existing features, and empowers our business with real-time insights to drive growth in market share, engagement, and revenue. We see 1 trillion events per year and process 10TB of data daily. What’s the job? Design, develop and deliver data products to production, complying with internal data governance, security and scalability of our system. Moving implementation to ownership of real-time and batch processing and data governance and policies. Maintain and enforce the business contracts on how data should be represented and stored. Stay on top of new technologies through R&D and prototyping to continuously improve our big data architectures and systems to streamline how we deliver value with high quality to our end users Implementing ETL processes, moving data between systems including S3, Snowflake, Kafka, and Spark. Work closely with our Data Scientists, SREs, and Product Managers to ensure software is high quality and meets user requirements. What We’ll Love About You 5+ years of experience working with data at scale, including data engineering, business intelligence, data science, or related field. 7+ years experience using Python, Experience using big data technologies (Snowflake, Airflow, Kubernetes, Docker, Helm, Spark, pySpark, ) Significant experience with relational databases and query authoring (SQL) in Snowflake or other distributed Databases. Experience with agile engineering practices such as TDD, Pair Programming, Continuous Integration, automated testing, and deployment. Experience with building stream-processing systems, using solutions such as Kafka, Storm or Spark-Streaming Experience with dimensional data modeling and schema design in Data Warehouses Familiar with ETL (managing high-quality reliable ETL pipelines) Be familiar with legal compliance (with data management tools) data classification, and retention. Location: Palo Alto, San Francisco or Chicago Salary Range: $165,000-$210,000 USD base. Equity. Medical, Dental, Vision. https://www.recruitingfromscratch.com/ Show more Show less | K4: Python, SQL, Snowflake, Airflow, Kubernetes, Docker, Helm, Spark, pySpark, Kafka, Storm, ETL, TDD, Pair programming, Continuous integration, Software testing, Deployment, Streamprocessing systems, Data modeling, Schema design, Data warehouses, Dimensional data modeling, Legal compliance, Data management
A5: Senior Data Engineer, Public Company | B5: Recruiting from Scratch | C5: Bloomington, IN | D5: https://www.linkedin.com/jobs/view/senior-data-engineer-public-company-at-recruiting-from-scratch-3744392289 | E5: 45277 | F5: Bloomington | G5: United States | H5: Mid senior | I5: Onsite | J5: This is for a client of Recruiting from Scratch. Who is Recruiting from Scratch: Recruiting from Scratch is a premier talent firm that focuses on placing the best product managers, software, and hardware talent at innovative companies. Our team is 100% remote and we work with teams across the United States to help them hire. We work with companies funded by the best investors including Sequoia Capital, Lightspeed Ventures, Tiger Global Management, A16Z, Accel, DFJ, and more. Our Client: They are a profitable dating application. Location: This is a hybrid role based in their Chicago office and will require you to be in office Tuesdays and Thursdays. What’s so interesting about this role? Our client is looking to bring on a Senior Data Engineer with chops in cutting edge real-time streaming technologies and ambitions to achieve high quality and reliability with TDD, automation, and continuous delivery. . In this role, you will have the opportunity to work with our product teams, building models and APIs to drive new features, delivers analysis to further improve engagement in existing features, and empowers our business with real-time insights to drive growth in market share, engagement, and revenue. We see 1 trillion events per year and process 10TB of data daily. What’s the job? Design, develop and deliver data products to production, complying with internal data governance, security and scalability of our system. Moving implementation to ownership of real-time and batch processing and data governance and policies. Maintain and enforce the business contracts on how data should be represented and stored. Stay on top of new technologies through R&D and prototyping to continuously improve our big data architectures and systems to streamline how we deliver value with high quality to our end users Implementing ETL processes, moving data between systems including S3, Snowflake, Kafka, and Spark. Work closely with our Data Scientists, SREs, and Product Managers to ensure software is high quality and meets user requirements. What We’ll Love About You 5+ years of experience working with data at scale, including data engineering, business intelligence, data science, or related field. 7+ years experience using Python, Experience using big data technologies (Snowflake, Airflow, Kubernetes, Docker, Helm, Spark, pySpark, ) Significant experience with relational databases and query authoring (SQL) in Snowflake or other distributed Databases. Experience with agile engineering practices such as TDD, Pair Programming, Continuous Integration, automated testing, and deployment. Experience with building stream-processing systems, using solutions such as Kafka, Storm or Spark-Streaming Experience with dimensional data modeling and schema design in Data Warehouses Familiar with ETL (managing high-quality reliable ETL pipelines) Be familiar with legal compliance (with data management tools) data classification, and retention. Location : This role is twice a week in a hybrid role minimum. Salary Range: $165,000-$210,000 USD base. Equity. Medical, Dental, Vision. https://www.recruitingfromscratch.com/ Show more Show less | K5: TDD, Automation, Continuous delivery, Data engineering, Data science, Business intelligence, Python, Snowflake, Airflow, Kubernetes, Docker, Helm, Spark, PySpark, SQL, Agile engineering, Pair programming, Continuous integration, Kafka, Storm, SparkStreaming, Data warehousing, ETL, Data classification, Data retention
A6: Senior Systems Engineer, Azure Data Platform | B6: Cook Medical | C6: Bloomington, IN | D6: https://www.linkedin.com/jobs/view/senior-systems-engineer-azure-data-platform-at-cook-medical-3775650947 | E6: 45277 | F6: Bloomington | G6: United States | H6: Mid senior | I6: Hybrid | J6: Overview We are seeking a talented Azure Cloud and Fabric Data Platform Engineer to play a pivotal role in ensuring the availability, performance, scalability, and security of our Azure-based data environments. In this position, you will collaborate closely with various teams to automate resource provisioning, maintain system integration, and oversee DevOps pipelines. Your responsibilities will include monitoring performance, conducting risk assessments, troubleshooting issues, and optimizing software delivery processes. Additionally, you'll provide technical support, create documentation, and stay updated on emerging technologies. If you are a proactive engineer ready to shape the future of our cloud ecosystem, we invite you to join our dynamic team and contribute to our organization's success. This role is a hybrid position. Candidate must reside within 2 hours via car of the Cook Medical location and is required to work onsite as needed per Manager expectations. For this position, qualified candidates must be legally authorized to be employed in the United States. Cook does not intend to provide sponsorship for employment visa status (e.g., H-1B or TN status) for this employment position. Responsibilities Configure and maintain Azure cloud and Fabric data platform to ensure availability, performance, scalability, and security of development, testing and production environments Communicate with other data team members, cross-IT teams, and key business stakeholders to identify required Azure resources and automate their provisioning Ensure integration with other systems and adherence to IT or business strategies. Serve as liaison with other teams, vendors, consultants, and customer groups to ensure cloud resources and DevOps pipelines are secure, scalable, resilient, monitored, and auditable Monitor overall performance to proactively identify potential issues and tune or improve environment appropriately Perform routine risk assessments for data platform systems and service levels Troubleshoot failed builds and deployments. Determine and fix environment and configuration issues. Analyze logs and communicate potential code issues to development teams Partner with development and cloud engineering teams to optimize the software delivery pipeline, ensuring smooth and efficient releases Provide technical support and troubleshoot issues related to Azure infrastructure, services and deployments to IT development teams Create and maintain technical documentation, guidelines, and DevOps knowledge base articles to facilitate knowledge sharing and collaboration within the team Estimate and manage life-cycle costs and product level roadmaps Stay up to date on new and emerging technologies Evaluate and recommend product standards and new purchases or subscriptions Plan, design, build, test, and implement IT infrastructure systems and technology. Deploy, install, integrate, maintain, and administer systems including hardware, software, and configurations. Lead the planning, life-cycle management, and development for systems. Regularly explore ways to scale, automate, and make service delivery more efficient. Create and maintain technical documentation on designs, engineering procedures, and implementation or operational work products. Work with others to establish and improve processes and procedures. Conduct technology or product exploration, prototypes, and pilots that deliver innovative IT solutions. Evaluate and recommend product standards and new purchases. Drive technical projects by determining scope, managing deliverables, and tracking progress for the creation or deployment of new solutions. Provide decision making, leadership, and coaching or mentoring to others in a group. Demonstrate strong communication skills and ability to thrive in a collaborative and independent environment. Qualifications Minimum four-year technical university degree or equivalent experience; advanced degree preferred. Minimum ten to twelve years of prior relevant work experience. Expert level industry technical certifications. Possess an expert level knowledge of subject matter. Performs work with a high degree of latitude. Handles the most complex issues and escalations from other staff. Physical Requirements Works under general office environment conditions Sitting for extended periods, utilizes close visual acuity for working with computers, equipment, etc. Must be able to perform the essential functions of the job, subject to reasonable accommodation requirements under the ADA Requires occasional early morning or late evening teleconferences International and domestic travel as required This role is a hybrid position. Candidate must reside within 2 hours via car of the Cook Medical location and is required to work onsite as needed per Manager expectations. For this position, qualified candidates must be legally authorized to be employed in the United States. Cook does not intend to provide sponsorship for employment visa status (e.g., H-1B or TN status) for this employment position. Show more Show less
A7: Senior Staff AI Data Engineer | B7: Recruiting from Scratch | C7: Bloomington, IN | D7: https://www.linkedin.com/jobs/view/senior-staff-ai-data-engineer-at-recruiting-from-scratch-3759712024 | E7: 45277 | F7: Bloomington | G7: United States | H7: Mid senior | I7: Hybrid | J7: Who is Recruiting from Scratch : Recruiting from Scratch is a premier talent firm that focuses on placing the best product managers, software, and hardware talent at innovative companies. Our team is 100% remote and we work with teams across the United States to help them hire. We work with companies funded by the best investors including Sequoia Capital, Lightspeed Ventures, Tiger Global Management, A16Z, Accel, DFJ, and more. https://www.recruitingfromscratch.com/ This is a hybrid role based in our Palo Alto, San Francisco or Chicago offices and will require you to be in office Tuesdays and Thursdays. What’s so interesting about this role? We believe that AI can revolutionize the dating industry. Our Data Engineer lead is responsible for building high quality ML datasets at scale, used to train ML models that power AI-centric features. In this pivotal role, you will have the opportunity to build foundational tools and data pipelines to ingest, normalize and clean the valuable data that would be fundamental for our ML engineers to build AI tools including recommendations, LLMs, ads, visual search, growth/notifications, trust and safety. What’s the job? We’re looking for an exceptional data engineer who is passionate about data for AI and values it can bring to our company, Who loves working with data ops at scale; and who is committed to the hard work necessary to continuously improve our ML data pipelines. In this position, you will be responsible for establishing and executing the strategy for our organization’s ML Data Engine, with an initial focus on agile ML Data OPs. This includes identification of infrastructure components and data stack to be used, design and implementation of pipelines between data systems and teams, automation workflows, data enrichment and monitoring tools all for AI models. As a tech lead specialized in data engineering, you are expected to code and contribute to the stack. Responsibilities: Dive into our dataset and design, implement and scale data pre/post processing pipelines of ML models Work on applied ML solutions in the areas of data mining, cleaning, normalizing and modeling Be self-motivated in seeking solutions when the correct path isn’t always known Collaborate with engineers in conceptualizing, planning and implementing data engineering initiatives working with different stakeholders Design and build data platforms & frameworks for processing high volumes of data, in real time as well as batch, that will be used across engineering teams Build data processing streams for cleaning and modeling text data for LLMs Research and evaluate new technologies in the big data space to guide our continuous improvement Collaborate with multi-functional teams to help tune the performance of large data applications Work with Privacy and Security team on data governance, risk and compliance initiatives Work on initiatives to ensure stability, performance and reliability of our data infrastructure What We’ll Love About You Bachelors in Computer Science, Mathematics, Physics, or a related fields 5+ years of experience as a data engineer building production-level pre/post-processing data pipelines for ML/DL models, including 2+ years of technical leadership experience Experience in statistical analysis & visualization on datasets using Pandas or R Experience designing and building highly available, distributed systems of data extraction, ingestion, normalization and processing of large data sets in real time as well as batch, that will be used across engineering teams using orchestration frameworks like Airflow, KubeFlow or other pipeline tools Demonstrated prior experience in creating data pipelines for text data sets NLP/ large language models Ability to produce well-engineered software, including appropriate automated test suites, technical documentation, and operational strategy Excellent coding skills in Python, Java, bash, SQL, and expertise with Git version control Experience using big data technologies (Snowflake, Airflow, Kubernetes, Docker, Helm, Spark, pySpark) Experience with any public cloud environment - AWS, GCP or Azure Significant experience with relational databases and query authoring (SQL) as well as NoSQL databases like DynamoDB etc Experience building and maintaining ETL (managing high-quality reliable ETL pipelines) We’ll really swoon if you have 2+ years of experience of technical leadership in building data engineering pipelines for AI Previous experience in building data pipeline for conversational AI APIs and recommender systems Experience with distributed systems and microservices Experience with Kubernetes and building Docker images Experience with building stream-processing systems, using solutions such as Kafka, Storm or Spark-Streaming Strong understanding of applied machine learning topics Be familiar with legal compliance (with data management tools) data classification, and retention Consistent track record of managing and implementing complex data projects What You'll Love About Us Mission and Impact: We are the world-leading LGBTQ social networking service. Your role will impact the lives of millions of LGBTQ people around the world Multiple Locations: We are hiring someone for this role to be based ideally in San Francisco or Palo Alto Family Insurance: Insurance premium coverage for health, dental, and vision for you and partial coverage for your dependents Retirement Savings: Generous 401K plan with 6% match and immediate vest in the US Compensation: Industry-competitive compensation and eligibility for company bonus and equity programs Queer-Inclusive Benefits: Industry-leading gender-affirming offerings with up to 90% cost coverage, access to Included Health, monthly stipends for HRT, and more Additional Benefits: Flexible vacation policy, monthly stipends for cell phone, internet, wellness, and food, one-time home-office setup stipend, and company-sponsored events Base Pay Range $160,000—$280,000 USD https://www.recruitingfromscratch.com/ Show more Show less | K7: Data Engineering, ML Data Ops, Data Mining, Data Cleaning, Data Normalization, Data Modeling, Data Enrichment, Data Monitoring, Data Platforms, Data Frameworks, Big Data Technologies, Data Pipelines, Machine Learning, Natural Language Processing, Large Language Models, Python, Java, Bash, SQL, Git, Snowflake, Airflow, Kubernetes, Docker, Helm, Spark, PySpark, AWS, GCP, Azure, NoSQL, ETL, Kafka, Storm, SparkStreaming, Applied Machine Learning, Data Management Tools, Data Classification, Data Retention, GenderAffirming Offerings, HR, Health, Dental, Vision
A8: Senior Staff AI Data Engineer | B8: Recruiting from Scratch | C8: Bloomington, IN | D8: https://www.linkedin.com/jobs/view/senior-staff-ai-data-engineer-at-recruiting-from-scratch-3773088678 | E8: 45277 | F8: Bloomington | G8: United States | H8: Mid senior | I8: Hybrid | J8: Who is Recruiting from Scratch : Recruiting from Scratch is a premier talent firm that focuses on placing the best product managers, software, and hardware talent at innovative companies. Our team is 100% remote and we work with teams across the United States to help them hire. We work with companies funded by the best investors including Sequoia Capital, Lightspeed Ventures, Tiger Global Management, A16Z, Accel, DFJ, and more. https://www.recruitingfromscratch.com/ This is a hybrid role based in our Palo Alto or San Francisco offices and will require you to be in office Tuesdays and Thursdays. What’s so interesting about this role? We believe that AI can revolutionize the dating industry. Our Data Engineer lead is responsible for building high quality ML datasets at scale, used to train ML models that power AI-centric features. In this pivotal role, you will have the opportunity to build foundational tools and data pipelines to ingest, normalize and clean the valuable data that would be fundamental for our ML engineers to build AI tools including recommendations, LLMs, ads, visual search, growth/notifications, trust and safety. What’s the job? We’re looking for an exceptional data engineer who is passionate about data for AI and values it can bring to our company, Who loves working with data ops at scale; and who is committed to the hard work necessary to continuously improve our ML data pipelines. In this position, you will be responsible for establishing and executing the strategy for our organization’s ML Data Engine, with an initial focus on agile ML Data OPs. This includes identification of infrastructure components and data stack to be used, design and implementation of pipelines between data systems and teams, automation workflows, data enrichment and monitoring tools all for AI models. As a tech lead specialized in data engineering, you are expected to code and contribute to the stack. Responsibilities: Dive into our dataset and design, implement and scale data pre/post processing pipelines of ML models Work on applied ML solutions in the areas of data mining, cleaning, normalizing and modeling Be self-motivated in seeking solutions when the correct path isn’t always known Collaborate with engineers in conceptualizing, planning and implementing data engineering initiatives working with different stakeholders Design and build data platforms & frameworks for processing high volumes of data, in real time as well as batch, that will be used across engineering teams Build data processing streams for cleaning and modeling text data for LLMs Research and evaluate new technologies in the big data space to guide our continuous improvement Collaborate with multi-functional teams to help tune the performance of large data applications Work with Privacy and Security team on data governance, risk and compliance initiatives Work on initiatives to ensure stability, performance and reliability of our data infrastructure What We’ll Love About You Bachelors in Computer Science, Mathematics, Physics, or a related fields 5+ years of experience as a data engineer building production-level pre/post-processing data pipelines for ML/DL models, including 2+ years of technical leadership experience Experience in statistical analysis & visualization on datasets using Pandas or R Experience designing and building highly available, distributed systems of data extraction, ingestion, normalization and processing of large data sets in real time as well as batch, that will be used across engineering teams using orchestration frameworks like Airflow, KubeFlow or other pipeline tools Demonstrated prior experience in creating data pipelines for text data sets NLP/ large language models Ability to produce well-engineered software, including appropriate automated test suites, technical documentation, and operational strategy Excellent coding skills in Python, Java, bash, SQL, and expertise with Git version control Experience using big data technologies (Snowflake, Airflow, Kubernetes, Docker, Helm, Spark, pySpark) Experience with any public cloud environment - AWS, GCP or Azure Significant experience with relational databases and query authoring (SQL) as well as NoSQL databases like DynamoDB etc Experience building and maintaining ETL (managing high-quality reliable ETL pipelines) We’ll really swoon if you have 2+ years of experience of technical leadership in building data engineering pipelines for AI Previous experience in building data pipeline for conversational AI APIs and recommender systems Experience with distributed systems and microservices Experience with Kubernetes and building Docker images Experience with building stream-processing systems, using solutions such as Kafka, Storm or Spark-Streaming Strong understanding of applied machine learning topics Be familiar with legal compliance (with data management tools) data classification, and retention Consistent track record of managing and implementing complex data projects What You'll Love About Us Mission and Impact: We are the world-leading LGBTQ social networking service. Your role will impact the lives of millions of LGBTQ people around the world Multiple Locations: We are hiring someone for this role to be based ideally in San Francisco or Palo Alto Family Insurance: Insurance premium coverage for health, dental, and vision for you and partial coverage for your dependents Retirement Savings: Generous 401K plan with 6% match and immediate vest in the US Compensation: Industry-competitive compensation and eligibility for company bonus and equity programs Queer-Inclusive Benefits: Industry-leading gender-affirming offerings with up to 90% cost coverage, access to Included Health, monthly stipends for HRT, and more Additional Benefits: Flexible vacation policy, monthly stipends for cell phone, internet, wellness, and food, one-time home-office setup stipend, and company-sponsored events Base Pay Range $160,000—$280,000 USD https://www.recruitingfromscratch.com/ Show more Show less | K8: Data Engineer, ML, Data Ops, Data Pipelines, Data Pre/post Processing, Data Mining, Data Cleaning, Data Normalization, Data Modeling, Data Platforms, Data Frameworks, Big Data, Data Governance, Data Infrastructure, Python, Java, Bash, SQL, Git, Snowflake, Airflow, Kubernetes, Docker, Helm, Spark, PySpark, AWS, GCP, Azure, NoSQL, DynamoDB, ETL, Kafka, Storm, SparkStreaming, Machine Learning, Data Compliance, Data Classification, Data Retention, Data Projects
A9: Data Scientist - National Defense/Python/SQL/AWS/MLOps/Clearances | B9: Motion Recruitment | C9: Laughlin AFB, TX | D9: https://www.linkedin.com/jobs/view/data-scientist-national-defense-python-sql-aws-mlops-clearances-at-motion-recruitment-3732144864 | E9: 45277 | F9: Del Rio | G9: United States | H9: Mid senior | I9: Hybrid | J9: An Artificial Intelligence/National Defense start-up is searching for Data Scientists to join their team. You would be solving complex problems by being a systems-level thinker, all the while transforming the nation’s defense and national security. This team handles abstract problems regarding the public policy surrounding climate change, energy, and national security, among other pressing issues. Some of your responsibilities would include discovering datasets that could help in solution development; curating data, analyzing, and performing quantitative modeling; validating the quality of data, models, and results; deploying and implementing solutions in collaboration with product team; and interacting with the product team on current and upcoming user requirements. Required Skills & Experience Masters or Ph.D. in Sciences, Mathematics or Engineering, especially numerical methods and simulations At least 4 years of professional experience in a Data Scientist position Python (pandas, numpy, scipy, sci-kit learn, etc) SQL / MySQL Cloud computing, preferably in an AWS environment Large-scale data processing and implementing batch processing pipelines in HPC or cloud architecture Active government clearance (secret, top secret, ts/sci - no Poly required) What You Will Be Doing Daily Responsibilities 70% Hands On 30% Team Collaboration The Offer Bonus eligible You Will Receive The Following Benefits Full medical, dental, vision coverage for employee and dependents 401k matching program PTO and Holidays Bonus and other incentive programs Access to mental health program Access to Flexible Spending Accounts for Health Care, Dependent and Commuter Applicants must be currently authorized to work in the US on a full-time basis now and in the future. Possession of at minimum a Secret Clearance is required.** Posted By: Lindsay Troyer Show more Show less | K9: Data Science, Numerical Methods, Simulations, Python, Pandas, Numpy, Scipy, Scikit Learn, SQL, MySQL, Cloud Computing, AWS, LargeScale Data Processing, Batch Processing Pipelines, HPC, Government Clearance, HandsOn Work, Team Collaboration, Bonus Eligibility, Full Medical Dental Vision Coverage, 401k Matching Program, PTO, Holidays, Bonus and Incentive Programs, Mental Health Program, Flexible Spending Accounts
A10: Python Data Engineer | B10: Kforce Inc | C10: Merrimack, NH | D10: https://www.linkedin.com/jobs/view/python-data-engineer-at-kforce-inc-3773539932 | E10: 45277 | F10: Inverell | G10: Australia | H10: Associate | I10: Onsite | J10: Responsibilities Kforce has a client in Merrimack, NH that is seeking a Python Data Engineer. Responsibilities: Handling various forms of unstructured and semi structured data and develop solutions to process these complex data Building data pipelines, API's, back-end services using Python Building containerized applications using docker, Kubernetes Processing and exposing data using AWS technologies like ec2, s3, Lambda, API Gateway, Load Balancers, Auto scaling, etc. Building data ingestion tools using technologies like Python to extract data from Relational Databases/Web Scraping/External API's Development working on Cloud/Big Data technologies Requirements BS in Computer Science or related degree, or equivalent experience 5 years of software development experience with at least 3 years working on Cloud/Big Data technologies Experience handling various forms of unstructured and semi structured data and develop solutions to process these complex data Strength in building data pipelines, API's, back-end services using Python Expertise in building containerized applications using docker, Kubernetes Experience in processing and exposing data using AWS technologies like ec2, s3, Lambda, API Gateway, Load Balancers, Auto scaling, etc. Expertise in building data ingestion tools using technologies like Python to extract data from Relational Databases/Web Scraping/External API's Experience in Snowflake or any MPP and columnar database on the Cloud Experience in CI/CD release automation and deployment (Jenkins, Concourse, CloudFormation, etc.) Snowflake or any MPP and columnar database on the Cloud CI/CD release automation and deployment (Jenkins, Concourse, CloudFormation, etc.) Understanding of overall AWS security services like KMS, IAM, Security groups, etc. Good understanding of overall AWS security services like KMS, IAM, Security groups, etc. Knowledge of Angular, Java and reporting tools like Power BI will be an added advantage The pay range is the lowest to highest compensation we reasonably in good faith believe we would pay at posting for this role. We may ultimately pay more or less than this range. Employee pay is based on factors like relevant education, qualifications, certifications, experience, skills, seniority, location, performance, union contract and business needs. This range may be modified in the future. We offer comprehensive benefits including medical/dental/vision insurance, HSA, FSA, 401(k), and life, disability & ADD insurance to eligible employees. Salaried personnel receive paid time off. Hourly employees are not eligible for paid time off unless required by law. Hourly employees on a Service Contract Act project are eligible for paid sick leave. Note: Pay is not considered compensation until it is earned, vested and determinable. The amount and availability of any compensation remains in Kforce's sole discretion unless and until paid and may be modified in its discretion consistent with the law. This job is not eligible for bonuses, incentives or commissions. Kforce is an Equal Opportunity/Affirmative Action Employer. All qualified applicants will receive consideration for employment without regard to race, color, religion, sex, pregnancy, sexual orientation, gender identity, national origin, age, protected veteran status, or disability status. Salary: $69 - $76 per hour Show more Show less
A11: Senior Health Data Migration Engineer Remote | B11: Steneral Consulting | C11: United States | D11: https://www.linkedin.com/jobs/view/senior-health-data-migration-engineer-remote-at-steneral-consulting-3642379153 | E11: 45277 | F11: Inverell | G11: Australia | H11: Mid senior | I11: Remote
A12: Senior ETL Data Quality Engineer | B12: Wise Skulls | C12: United States | D12: https://www.linkedin.com/jobs/view/senior-etl-data-quality-engineer-at-wise-skulls-3748439902 | E12: 45277 | F12: Inverell | G12: Australia | H12: Mid senior | I12: Remote | J12: Title: Senior ETL Data Quality Engineer Location: Austin, TX; Fortmill, SC (Remote for Now) Duration: 12+ Months (Possibility of Extension) Implementation Partner: Infosys End Client: To be disclosed Jd Must have 9+ Years of Expereince. Must have ETL, SQL, Postgres, Cloud (Snowflake, AWS), Automation (Python or Java), CI/CD. Good to have API. Show more Show less | K12: ETL, SQL, PostgreSQL, Cloud, Snowflake, AWS, Python, Java, CI/CD, API
A13: Senior Engineer, Data | B13: Ensemble Health Partners | C13: United States | D13: https://www.linkedin.com/jobs/view/senior-engineer-data-at-ensemble-health-partners-3780820485 | E13: 45277 | F13: Inverell | G13: Australia | H13: Mid senior | I13: Remote | J13: Thank you for considering a career at Ensemble Health Partners! Ensemble Health Partners is a leading provider of technology-enabled revenue cycle management solutions for health systems, including hospitals and affiliated physician groups. They offer end-to-end revenue cycle solutions as well as a comprehensive suite of point solutions to clients across the country. Ensemble keeps communities healthy by keeping hospitals healthy. We recognize that healthcare requires a human touch, and we believe that every touch should be meaningful. This is why our people are the most important part of who we are. By empowering them to challenge the status quo, we know they will be the difference The Opportunity: As a Senior Data Engineer your role will be to implement the technology strategy for Ensemble data engineering team. You will focus on developing reusable software components, patterns, and tooling to address them. You will influence behaviors through code reviews and hands on design sessions. Your outcomes will be a primary contributor to achieving our long-term strategic goals. Develop, test, deploy, monitor, maintain, and continuously improve scalable data pipelines and builds our new API integrations to support continuing increases in data volume and complexity. Translate product concepts into project commitments that deliver incremental value to our customers frequently and with high quality. Actively contribute to the engineering team through code reviews and hands on design sessions. Implements processes and systems to monitor data quality, ensuring production data is always accurate and available for key stakeholders and business processes that depend on it. Review and recommend architectural patterns for data access and performance that align with the company’s best practices and platforms. Required Minimum Education: 4 year/ Bachelors Degree or equivalent of working experience at the level Preferred Education: Graduate Degree (Masters) Other Knowledge, Skills and Abilities Required: 5+ years of coding experience with Microsoft SQL. 3+ years working with big data technologies including but not limited to Databricks, Apache Spark, Python, Microsoft Azure (Data Factory, Dataflows, Azure Functions, Azure Service Bus) with a willingness and ability to learn new ones. Experience and proficient understanding of MS Azure Data Bricks Experience and proficiency in MS SQL- able to create and perform query and codes. Excellent understanding of engineering fundamentals: testing automation, code reviews, telemetry, iterative delivery and DevOps Experience with polyglot storage architectures including relational, columnar, key-value, graph or equivalent Experience with Delta tables as well as Parquet files stored in ADLS Experience delivering applications using componentized and distributed architectures using event driven patterns Demonstrated ability to communicate effectively to both technical and non-technical, globally distributed audiences Solid foundations in formal architecture, design patterns and best practices Understanding and experience working in a healthcare environment is strongly preferred. Join An Award-winning Company Three-time winner of “Best in KLAS” 2020-2022 2022 Top Workplaces Healthcare Industry Award 2022 Top Workplaces USA Award 2022 Top Workplaces Culture Excellence Awards Innovation Work-Life Flexibility Leadership Purpose + Values Bottom line, we believe in empowering people and giving them the tools and resources needed to thrive. A few of those include: Associate Benefits – We offer a comprehensive benefits package designed to support the physical, emotional, and financial health of you and your family, including healthcare, time off, retirement, and well-being programs. Our Culture – Ensemble is a place where associates can do their best work and be their best selves. We put people first, last and always. Our culture is rooted in collaboration, growth, and innovation. Growth – We invest in your professional development. Each associate will earn a professional certification relevant to their field and can obtain tuition reimbursement. Recognition – We offer quarterly and annual incentive programs for all employees who go beyond and keep raising the bar for themselves and the company. Ensemble Health Partners is an equal employment opportunity employer. It is our policy not to discriminate against any applicant or employee based on race, color, sex, sexual orientation, gender, gender identity, religion, national origin, age, disability, military or veteran status, genetic information or any other basis protected by applicable federal, state, or local laws. Ensemble Health Partners also prohibits harassment of applicants or employees based on any of these protected categories. Ensemble Health Partners provides reasonable accommodations to qualified individuals with disabilities in accordance with the Americans with Disabilities Act and applicable state and local law. If you require accommodation in the application process, please contact TA@ensemblehp.com. EEOC – Know Your Rights FMLA Rights - English La FMLA Español Show more Show less | K13: SQL, Databricks, Apache Spark, Python, Azure Functions, Azure Data Bricks, MS SQL, Azure Service Bus, Azure Data Factory, Azure Dataflows, DevOps, Delta tables, AWS, Parquet files, Healthcare
A14: Senior Data Engineer | B14: Attune | C14: New York, NY | D14: https://www.linkedin.com/jobs/view/senior-data-engineer-at-attune-3711772375 | E14: 45277 | F14: Inverell | G14: Australia | H14: Mid senior | I14: Remote | J14: Attune is making it easier, faster, and more reliable for small businesses to access insurance (think, pizza place down the street or main street store). They all need insurance to protect their businesses, but when it comes time to get a policy, they're bogged down by hundreds of questions, lots of paperwork, and a seemingly never-ending timeline stretching for weeks or months. We are changing all that. By using data and technology expertise to understand risk, automating legacy processes, and creating a better user experience for brokers, we're able to provide policies that are more applicable and more transparent in just minutes. Simply put, we're pushing insurance into the future, focusing on accuracy, speed, and ease. Our mission and our team are growing. In staying true to our values, we've earned our spot on many workplace award lists. Attune is dedicated to creating a diverse team of curious, focused, and motivated people who are excited about changing the future of an entire industry. Job Description As a Senior Data Engineer joining our growing Data team, you will serve as a leader for data engineering - helping maintain our existing data pipelines and internal web applications while also providing guidance and support to other team members and looking for ways to improve our code and architecture to meet our growing data needs. You will also work with team members across the organization to develop and test new pipelines as we launch new products and integrate with third-party data sources. We work with various tools including Python/Pandas, Postgresql, Bash, AWS EC2, and S3. We are always open to using whatever tool is best for the job. Responsibilities: Independently drive improvements and optimization in ETLs and internal apps with a focus on future scalability and performance Serve as a leader/mentor for data engineering, employing and encouraging good software and pipeline development practices Develop automated checks to ensure data quality and integrity Maintain and improve batch ETL jobs - including SQL query optimization, bug fixes and code improvements Work with our data engineers, BI, and other teams across the business to develop/refine ETL processes Understand and answer questions on the data our team maintains & influence business decisions in the process, in partnership with Revenue, Marketing, and Underwriting Qualifications: 5+ years experience in analytics, data science, or data engineering role building & maintaining ETL pipelines Expert Python and Postgresql skills Solid understanding of relational database design and basic query optimization techniques Experience working with/optimizing for medium to large datasets in SQL Experience working with git, and Gitlab or Github Nice to have: Experience with Linux CLI, shell programming Understanding of CI/CD Experience with AWS EC2 and S3 What we offer you: 150-190k per year Flexible PTO Generous parental and caregiver leave 401K match Excellent medical, dental, and vision plans Remote-first culture And more! Show more Show less | K14: Python, Pandas, PostgreSQL, Bash, AWS EC2, S3, SQL, Git, GitLab, Github, Linux, CLI, Shell programming, CI/CD
A15: Sr. Data Software Engineer | B15: Steneral Consulting | C15: United States | D15: https://www.linkedin.com/jobs/view/sr-data-software-engineer-at-steneral-consulting-3733275905 | E15: 45277 | F15: Inverell | G15: Australia | H15: Mid senior | I15: Remote | J15: Job : Sr. Data Software Engineer Location: 100% Remote Duration: 6 month Contract to Hire (USC/ GC Holder ONLY) Top Skills SQL Azure Data Factory DBT ETL work Proven ability to complete projects in a timely manner while clearly measuring progress Strong software engineering fundamentals (data structures, algorithms, async programming patterns, object-oriented design, parallel programming) Strong understanding and demonstrated experience with at least one popular programming language (.NET or Java) and SQL constructs. Experience writing and maintaining frontend client applications, Angular preferred Strong experience with revision control (Git) Experience with cloud-based systems (Azure / AWS / GCP). High level understanding of big data design (data lake, data mesh, data warehouse) and data normalization patterns Demonstrated experience with Queuing technologies (Kafka / SNS / RabbitMQ etc) Demonstrated experience with Metrics, Logging, Monitoring and Alerting tools Strong communication skills Strong experience with use of RESTful APIs High level understanding of HL7 V2.x / FHIR based interface messages. High level understanding of system deployment tasks and technologies. (CI/CD Pipeline, K8s, Terraform). Project/Day To Day Communicate with business leaders to help translate requirements into functional specification Develop broad understanding of business logic and functionality of current systems Analyze and manipulate data by writing and running SQL queries Analyze logs to identify and prevent potential issues from occurring Deliver clean and functional code in accordance with business requirements Consume data from any source, such a flat files, streaming systems, or RESTful APIs Interface with Electronic Health Records Engineer scalable, reliable, and performant systems to manage data Collaborate closely with other Engineers, QA, Scrum master, Product Manager in your team as well as across the organization Build quality systems while expanding offerings to dependent teams Comfortable in multiple roles, from Design and Development to Code Deployment to and monitoring and investigating in production systems. Show more Show less | K15: SQL, Azure, Data Factory, DBT, ETL, Data structures, Algorithms, Async programming, Objectoriented design, Parallel programming, .NET, Java, Angular, Git, Cloudbased systems, Big data design, Data normalization, Queuing technologies, Metrics, Logging, Monitoring, Alerting, RESTful APIs, HL7 V2.x / FHIR, CI/CD Pipeline, K8s, Terraform, Electronic Health Records
A16: Data Analyst || Remote | B16: Steneral Consulting | C16: United States | D16: https://www.linkedin.com/jobs/view/data-analyst-remote-at-steneral-consulting-3673756434 | E16: 45277 | F16: Inverell | G16: Australia | H16: Mid senior | I16: Remote | J16: Can be 100% remote; if someone could come onsite some on the front end of the engagement, that would be ideal to help them get up to speed (could put the person up in a corporate hotel around them in Athens, GA) Need LinkedIn Candidates need to taker a video screen with prime vendor prior to end client submittal Must Have 5+ years' experience Data Analysis & Modeling Working knowledge of the Google Cloud Storage and Google BigQuery Knowledge and familiarity of Google Looker (LookML) and/or Power BI (DAX) Strong ANSI SQL experience (DDL, views, stored procedures) Experience collaborating with data engineers and business users to create realistic solutions to business problems Ability to understand business structure and process to determine what measures and KPI's can be gleaned from existing data Strong ability to articulate and explain situations, issues and solutions to members of the organization not regularly involved in data management Job Description The Data Analyst will be responsible for requirements gathering, data modeling within new and existing components for our client's data ecosystem. He or she will have a thorough understanding of relational databases, as well as reporting & visualization technologies. There will be a focus on using raw and partially refined data to configure models and semantic layers within applicable reporting and business intelligence tools throughout the organization to support strategic initiatives. The candidate will need to be comfortable with engaging different areas of the business to gather requirements, evaluate circumstances, and produce results under the guidance of a senior data architect. Essential Job Functions Author and support data models within the semantic layers of relevant data visualization and BI tools Author and support tables, views, and procedures within relational data warehousing technology to effectively ready data for consumption within relevant BI toolsets Create, support, and distribute reports and visualizations using applicable tools available to our client's brand Display a high level of competence with relevant BI tools (Looker, Power BI, etc.) in such a way that business analysts and other end users have the proper guidance on how to use the technology Research and stay abreast of industry leading technologies that improve business intelligence and create highly usable data models Participate in requirements gathering and brainstorming sessions, and be willing to suggest and provide innovative solutions to complex business problems Partner with various groups throughout the organization to create collaborative solutions to meet business needs Collaborate with other teams within IT to create a cohesive integration of systems and data Validate, massage and clean data from all available sources to ensure the highest degree of accuracy and usability Understand and perform to standards within project plans set forth by leaders of the organization and the Project Management Office Qualifications Working knowledge of the Google Cloud Storage and Google BigQuery Knowledge and familiarity of Google Looker (LookML) and/or Power BI (DAX) Strong ANSI SQL experience (DDL, views, stored procedures) Experience collaborating with data engineers and business users to create realistic solutions to business problems Ability to understand business structure and process to determine what measures and KPI's can be gleaned from existing data Strong ability to articulate and explain situations, issues and solutions to members of the organization not regularly involved in data management Ability to join and contribute effectively to large meetings with individuals from various departments within the organization and at various levels Proficient in common offerings within Office 365 product suite (Word, PowerPoint, Excel) Education And Experience Guidelines Education: Bachelor's degree in Computer Science, Information Systems, Data Science, or related field Experience: 5+ years of experience in Data Analysis and Modeling Show more Show less | K16: Data Analysis, Data Modeling, Google Cloud Storage, Google BigQuery, Google Looker (LookML), Power BI (DAX), ANSI SQL, Relational Databases, Reporting & Visualization Technologies, Business Intelligence Tools, Data Visualization, Data Warehousing, Data Cleaning, Data Validation, Project Management, Office 365 (Word PowerPoint Excel), Business Requirements Gathering, Brainstorming, Problem Solving, Communication, Collaboration, Teamwork
